2021-09-11 12:45:19,111 INFO    MainThread:25628 [internal.py:wandb_internal():86] W&B internal server running at pid: 25628, started at: 2021-09-11 12:45:19.102494
2021-09-11 12:45:19,113 INFO    WriterThread:25628 [datastore.py:open_for_write():77] open: C:\Programming\rl_cooperation\Pygame_RL_cooperation\wandb\offline-run-20210911_124518-l251hrle\run-l251hrle.wandb
2021-09-11 12:45:19,113 DEBUG   HandlerThread:25628 [handler.py:handle_request():126] handle_request: run_start
2021-09-11 12:45:19,130 DEBUG   HandlerThread:25628 [meta.py:__init__():40] meta init
2021-09-11 12:45:19,131 DEBUG   HandlerThread:25628 [meta.py:__init__():54] meta init done
2021-09-11 12:45:19,131 DEBUG   HandlerThread:25628 [meta.py:probe():211] probe
2021-09-11 12:45:19,202 DEBUG   HandlerThread:25628 [git.py:repo():33] git repository is invalid
2021-09-11 12:45:19,202 DEBUG   HandlerThread:25628 [meta.py:_save_pip():58] save pip
2021-09-11 12:45:19,203 DEBUG   HandlerThread:25628 [meta.py:_save_pip():72] save pip done
2021-09-11 12:45:19,203 DEBUG   HandlerThread:25628 [meta.py:probe():249] probe done
2021-09-11 12:46:54,717 WARNING MainThread:25628 [internal.py:wandb_internal():145] Internal process interrupt: 1
2021-09-11 12:46:54,941 WARNING MainThread:25628 [internal.py:wandb_internal():145] Internal process interrupt: 2
2021-09-11 12:46:54,941 ERROR   MainThread:25628 [internal.py:wandb_internal():148] Internal process interrupted.
2021-09-11 12:46:55,167 INFO    SenderThread:25628 [sender.py:finish():979] shutting down sender
2021-09-11 12:46:55,806 INFO    WriterThread:25628 [datastore.py:close():281] close: C:\Programming\rl_cooperation\Pygame_RL_cooperation\wandb\offline-run-20210911_124518-l251hrle\run-l251hrle.wandb
