

1975it [00:03, 562.91it/s]C:\Programming\rl_cooperation\lib\site-packages\torch\nn\modules\loss.py:907: UserWarning: Using a target size (torch.Size([1000, 1000])) that is different to the input size (torch.Size([1000])). This will likely lead to incorrect results due to broadcasting. Please ensure they have the same size.
  return F.smooth_l1_loss(input, target, reduction=self.reduction, beta=self.beta)


























































17031it [02:01, 157.39it/s]
17106it [02:02, 125.93it/s]Traceback (most recent call last):
  File "c:\Programming\rl_cooperation\DQN_breakout\agent.PY", line 151, in <module>
    main(False)
  File "c:\Programming\rl_cooperation\DQN_breakout\agent.PY", line 147, in main
    torch.save(tgt.state_dict(),f"model/{step_num}.pth")
  File "C:\Programming\rl_cooperation\lib\site-packages\torch\serialization.py", line 369, in save
    with _open_file_like(f, 'wb') as opened_file:
  File "C:\Programming\rl_cooperation\lib\site-packages\torch\serialization.py", line 230, in _open_file_like
    return _open_file(name_or_buffer, mode)
  File "C:\Programming\rl_cooperation\lib\site-packages\torch\serialization.py", line 211, in __init__
    super(_open_file, self).__init__(open(name, mode))
FileNotFoundError: [Errno 2] No such file or directory: 'model/15151.pth'